tests/scorpiussigma-custom.in
5
o
0 B 201 AMZN 3250 1000
0 B 202 AMZN 3260 100
0 B 203 AMZN 3260 100
0 B 204 AMZN 3260 100
0 B 205 AMZN 3260 100
1 B 206 AMZN 3260 100
1 B 207 AMZN 3260 100
1 B 208 AMZN 3260 100
1 B 209 AMZN 3260 100
3 S 210 AMZN 3250 10
3 S 211 AMZN 3250 10
3 S 212 AMZN 3250 10
3 S 213 AMZN 3250 10
3 S 214 AMZN 3250 10
3 S 215 AMZN 3250 10
3 S 216 AMZN 3250 10
3 S 217 AMZN 3250 10
4 S 218 AMZN 3250 10
4 S 219 AMZN 3250 10
4 S 220 AMZN 3250 10
4 S 221 AMZN 3250 10
4 S 222 AMZN 3250 10
4 S 223 AMZN 3250 10
4 S 224 AMZN 3250 10
2 B 225 AMZN 3260 100
2 B 226 AMZN 3260 100
2 B 227 AMZN 3260 100
2 B 228 AMZN 3260 100
2 B 229 AMZN 3260 100
2 B 230 AMZN 3260 100
2 B 231 AMZN 3260 100
4 S 232 AMZN 3250 10
x
